2025-10-05 10:29:17,679 INFO [34mroot[0m: File logging enabled: /Users/zvwgvx/PycharmProjects/Ryuuko-Chatbot/logs/ryuuko.log
2025-10-05 10:29:17,683 INFO [34mroot[0m: Log rotation: daily, keeping 30 days
2025-10-05 10:29:17,683 INFO [34mroot[0m: Compressed archives will be created in: /Users/zvwgvx/PycharmProjects/Ryuuko-Chatbot/logs
2025-10-05 10:29:17,683 INFO [34mroot[0m: Starting application...
2025-10-05 10:29:17,683 INFO [34mConfig.Loader[0m: [SYNC] Initializing MongoDB connection to: polydevsdb
2025-10-05 10:29:22,725 ERROR [34mroot[0m: Fatal error occurred: ‚ùå Cannot connect to MongoDB at mongodb://polydevs:xr3EQcG2WszUFcdXx1E6ND7u3jWj1Mabv3UaYeF73RjUddq2FQh6Wwd1P3XmUDTp@192.168.2.254/polydevsdb?authSource=admin. Is MongoDB running?
Traceback (most recent call last):
  File "/Users/zvwgvx/PycharmProjects/Ryuuko-Chatbot/src/config/loader.py", line 152, in init_storage
    test_client.admin.command('ping')
  File "/Users/zvwgvx/PycharmProjects/Ryuuko-Chatbot/.venv/lib/python3.9/site-packages/pymongo/_csot.py", line 125, in csot_wrapper
    return func(self, *args, **kwargs)
  File "/Users/zvwgvx/PycharmProjects/Ryuuko-Chatbot/.venv/lib/python3.9/site-packages/pymongo/synchronous/database.py", line 931, in command
    with self._client._conn_for_reads(read_preference, session, operation=command_name) as (
  File "/Users/zvwgvx/PycharmProjects/Ryuuko-Chatbot/.venv/lib/python3.9/site-packages/pymongo/synchronous/mongo_client.py", line 1885, in _conn_for_reads
    server = self._select_server(read_preference, session, operation)
  File "/Users/zvwgvx/PycharmProjects/Ryuuko-Chatbot/.venv/lib/python3.9/site-packages/pymongo/synchronous/mongo_client.py", line 1833, in _select_server
    server = topology.select_server(
  File "/Users/zvwgvx/PycharmProjects/Ryuuko-Chatbot/.venv/lib/python3.9/site-packages/pymongo/synchronous/topology.py", line 409, in select_server
    server = self._select_server(
  File "/Users/zvwgvx/PycharmProjects/Ryuuko-Chatbot/.venv/lib/python3.9/site-packages/pymongo/synchronous/topology.py", line 387, in _select_server
    servers = self.select_servers(
  File "/Users/zvwgvx/PycharmProjects/Ryuuko-Chatbot/.venv/lib/python3.9/site-packages/pymongo/synchronous/topology.py", line 294, in select_servers
    server_descriptions = self._select_servers_loop(
  File "/Users/zvwgvx/PycharmProjects/Ryuuko-Chatbot/.venv/lib/python3.9/site-packages/pymongo/synchronous/topology.py", line 344, in _select_servers_loop
    raise ServerSelectionTimeoutError(
pymongo.errors.ServerSelectionTimeoutError: No servers found yet, Timeout: 5.0s, Topology Description: <TopologyDescription id: 68e1e60d100c75959553b4c4, topology_type: Unknown, servers: [<ServerDescription ('192.168.2.254', 27017) server_type: Unknown, rtt: None>]>

During handling of the above exception, another exception occurred:

Traceback (most recent call last):
  File "/Users/zvwgvx/PycharmProjects/Ryuuko-Chatbot/src/__main__.py", line 35, in main
    loader.init_storage()
  File "/Users/zvwgvx/PycharmProjects/Ryuuko-Chatbot/src/config/loader.py", line 162, in init_storage
    raise RuntimeError(f"‚ùå Cannot connect to MongoDB at {MONGODB_CONNECTION_STRING}. Is MongoDB running?")  # Keep emoji for user error
RuntimeError: ‚ùå Cannot connect to MongoDB at mongodb://polydevs:xr3EQcG2WszUFcdXx1E6ND7u3jWj1Mabv3UaYeF73RjUddq2FQh6Wwd1P3XmUDTp@192.168.2.254/polydevsdb?authSource=admin. Is MongoDB running?
2025-10-05 13:22:01,361 INFO [34mroot[0m: File logging enabled: /Users/zvwgvx/PycharmProjects/Ryuuko-Chatbot/logs/ryuuko.log
2025-10-05 13:22:01,361 INFO [34mroot[0m: Log rotation: daily, keeping 30 days
2025-10-05 13:22:01,361 INFO [34mroot[0m: Compressed archives will be created in: /Users/zvwgvx/PycharmProjects/Ryuuko-Chatbot/logs
2025-10-05 13:22:01,361 INFO [34mroot[0m: Starting application...
2025-10-05 13:22:01,362 INFO [34mConfig.Loader[0m: [SYNC] Initializing MongoDB connection to: polydevsdb
2025-10-05 13:22:05,645 INFO [34mroot[0m: Received shutdown signal, stopping gracefully...
